<?xml version="1.0" encoding="UTF-8"?>
<testng-results skipped="0" failed="1" ignored="0" total="1" passed="0">
  <reporter-output>
  </reporter-output>
  <suite name="Default suite" duration-ms="80445" started-at="2018-09-11T14:52:01Z" finished-at="2018-09-11T14:53:21Z">
    <groups>
    </groups>
    <test name="Default test" duration-ms="80445" started-at="2018-09-11T14:52:01Z" finished-at="2018-09-11T14:53:21Z">
      <class name="test.TestCreatePostWithAttachment">
        <test-method status="PASS" signature="setup()[pri:0, instance:test.TestCreatePostWithAttachment@59f99ea]" name="setup" is-config="true" duration-ms="11683" started-at="2018-09-11T14:52:01Z" finished-at="2018-09-11T14:52:13Z">
          <reporter-output>
          </reporter-output>
        </test-method> <!-- setup -->
        <test-method status="FAIL" signature="test_Create_Chatter_Post_Attachment()[pri:0, instance:test.TestCreatePostWithAttachment@59f99ea]" name="test_Create_Chatter_Post_Attachment" duration-ms="67538" started-at="2018-09-11T14:52:13Z" finished-at="2018-09-11T14:53:20Z">
          <exception class="java.lang.AssertionError">
            <message>
              <![CDATA[expected [true] but found [false]]]>
            </message>
            <full-stacktrace>
              <![CDATA[java.lang.AssertionError: expected [true] but found [false]
at org.testng.Assert.fail(Assert.java:96)
at org.testng.Assert.failNotEquals(Assert.java:776)
at org.testng.Assert.assertTrue(Assert.java:44)
at org.testng.Assert.assertTrue(Assert.java:54)
at test.TestCreatePostWithAttachment.test_Create_Chatter_Post_Attachment(TestCreatePostWithAttachment.java:53)
at sun.reflect.NativeMethodAccessorImpl.invoke0(Native Method)
at sun.reflect.NativeMethodAccessorImpl.invoke(Unknown Source)
at sun.reflect.DelegatingMethodAccessorImpl.invoke(Unknown Source)
at java.lang.reflect.Method.invoke(Unknown Source)
at org.testng.internal.MethodInvocationHelper.invokeMethod(MethodInvocationHelper.java:124)
at org.testng.internal.Invoker.invokeMethod(Invoker.java:580)
at org.testng.internal.Invoker.invokeTestMethod(Invoker.java:716)
at org.testng.internal.Invoker.invokeTestMethods(Invoker.java:988)
at org.testng.internal.TestMethodWorker.invokeTestMethods(TestMethodWorker.java:125)
at org.testng.internal.TestMethodWorker.run(TestMethodWorker.java:109)
at org.testng.TestRunner.privateRun(TestRunner.java:648)
at org.testng.TestRunner.run(TestRunner.java:505)
at org.testng.SuiteRunner.runTest(SuiteRunner.java:455)
at org.testng.SuiteRunner.runSequentially(SuiteRunner.java:450)
at org.testng.SuiteRunner.privateRun(SuiteRunner.java:415)
at org.testng.SuiteRunner.run(SuiteRunner.java:364)
at org.testng.SuiteRunnerWorker.runSuite(SuiteRunnerWorker.java:52)
at org.testng.SuiteRunnerWorker.run(SuiteRunnerWorker.java:84)
at org.testng.TestNG.runSuitesSequentially(TestNG.java:1208)
at org.testng.TestNG.runSuitesLocally(TestNG.java:1137)
at org.testng.TestNG.runSuites(TestNG.java:1049)
at org.testng.TestNG.run(TestNG.java:1017)
at org.testng.remote.AbstractRemoteTestNG.run(AbstractRemoteTestNG.java:114)
at org.testng.remote.RemoteTestNG.initAndRun(RemoteTestNG.java:251)
at org.testng.remote.RemoteTestNG.main(RemoteTestNG.java:77)
]]>
            </full-stacktrace>
          </exception> <!-- java.lang.AssertionError -->
          <reporter-output>
          </reporter-output>
        </test-method> <!-- test_Create_Chatter_Post_Attachment -->
        <test-method status="PASS" signature="exit()[pri:0, instance:test.TestCreatePostWithAttachment@59f99ea]" name="exit" is-config="true" duration-ms="1183" started-at="2018-09-11T14:53:20Z" finished-at="2018-09-11T14:53:21Z">
          <reporter-output>
          </reporter-output>
        </test-method> <!-- exit -->
      </class> <!-- test.TestCreatePostWithAttachment -->
    </test> <!-- Default test -->
  </suite> <!-- Default suite -->
</testng-results>
